<?xml version="1.0" ?>
<!-- =================================================================================== -->
<!-- |    This document was autogenerated by xacro from robot.urdf.xacro               | -->
<!-- |    EDITING THIS FILE BY HAND IS NOT RECOMMENDED                                 | -->
<!-- =================================================================================== -->
<robot name="robot">
  <!--
        A fictitious robot model for testing purposes.
        The kinematics is roughly inspired by the universal robots ur10.
        -->
  <!-- colors -->
  <material name="grey">
    <color rgba="0.3 0.3 0.3 1.0"/>
  </material>
  <link name="base_link">
    <visual name="joint">
      <origin rpy="0 0 0" xyz="0 0 0.015"/>
      <geometry>
        <cylinder length="0.03" radius="0.02"/>
      </geometry>
      <material name="grey"/>
    </visual>
  </link>
  <joint name="joint1" type="revolute">
    <parent link="base_link"/>
    <child link="link1"/>
    <origin rpy="0.0 0.0 0.0" xyz="0.0 0.0 0.045"/>
    <axis xyz="0 0 1"/>
    <limit effort="1.0" lower="-6.283185307179586" upper="6.283185307179586" velocity="10.0"/>
  </joint>
  <link name="link1">
    <visual name="joint1">
      <origin rpy="0 0 0" xyz="0 0 0"/>
      <geometry>
        <cylinder length="0.03" radius="0.02"/>
      </geometry>
      <material name="grey"/>
    </visual>
    <visual name="link">
      <origin rpy="0 0 0" xyz="0 0 0.075"/>
      <geometry>
        <cylinder length="0.15" radius="0.01"/>
      </geometry>
      <material name="grey"/>
    </visual>
    <visual name="joint2">
      <origin rpy="1.5707963267948966 0 0" xyz="0 0 0.15"/>
      <geometry>
        <cylinder length="0.03" radius="0.02"/>
      </geometry>
      <material name="grey"/>
    </visual>
  </link>
  <joint name="joint2" type="revolute">
    <parent link="link1"/>
    <child link="link2"/>
    <origin rpy="0.0 1.5707963267948966 0.0" xyz="0.0 0.03 0.15"/>
    <axis xyz="0 1 0"/>
    <limit effort="1.0" lower="-6.283185307179586" upper="6.283185307179586" velocity="10.0"/>
  </joint>
  <link name="link2">
    <visual name="joint2">
      <origin rpy="1.5707963267948966 0 0" xyz="0 0 0"/>
      <geometry>
        <cylinder length="0.03" radius="0.02"/>
      </geometry>
      <material name="grey"/>
    </visual>
    <visual name="link">
      <origin rpy="0 0 0" xyz="0 0 0.25"/>
      <geometry>
        <cylinder length="0.5" radius="0.01"/>
      </geometry>
      <material name="grey"/>
    </visual>
    <visual name="joint3">
      <origin rpy="1.5707963267948966 0 0" xyz="0 0 0.5"/>
      <geometry>
        <cylinder length="0.03" radius="0.02"/>
      </geometry>
      <material name="grey"/>
    </visual>
  </link>
  <joint name="joint3" type="revolute">
    <parent link="link2"/>
    <child link="link3"/>
    <origin rpy="0.0 0.0 0.0" xyz="0.0 -0.03 0.5"/>
    <axis xyz="0 1 0"/>
    <limit effort="1.0" lower="-3.141592653589793" upper="3.141592653589793" velocity="10.0"/>
  </joint>
  <link name="link3">
    <visual name="joint3">
      <origin rpy="1.5707963267948966 0 0" xyz="0 0 0"/>
      <geometry>
        <cylinder length="0.03" radius="0.02"/>
      </geometry>
      <material name="grey"/>
    </visual>
    <visual name="link">
      <origin rpy="0 0 0" xyz="0 0 0.25"/>
      <geometry>
        <cylinder length="0.5" radius="0.01"/>
      </geometry>
      <material name="grey"/>
    </visual>
    <visual name="joint4">
      <origin rpy="1.5707963267948966 0 0" xyz="0 0 0.5"/>
      <geometry>
        <cylinder length="0.03" radius="0.02"/>
      </geometry>
      <material name="grey"/>
    </visual>
  </link>
  <joint name="joint4" type="revolute">
    <parent link="link3"/>
    <child link="link4"/>
    <origin rpy="0.0 1.5707963267948966 0.0" xyz="0.0 0.03 0.5"/>
    <axis xyz="0 1 0"/>
    <limit effort="1.0" lower="-6.283185307179586" upper="6.283185307179586" velocity="10.0"/>
  </joint>
  <link name="link4">
    <visual name="joint4">
      <origin rpy="1.5707963267948966 0 0" xyz="0 0 0"/>
      <geometry>
        <cylinder length="0.03" radius="0.02"/>
      </geometry>
      <material name="grey"/>
    </visual>
    <visual name="link">
      <origin rpy="1.5707963267948966 0 0" xyz="0 0.075 0"/>
      <geometry>
        <cylinder length="0.15" radius="0.01"/>
      </geometry>
      <material name="grey"/>
    </visual>
    <visual name="joint5">
      <origin rpy="0 0 0" xyz="0 0.15 0"/>
      <geometry>
        <cylinder length="0.03" radius="0.02"/>
      </geometry>
      <material name="grey"/>
    </visual>
  </link>
  <joint name="joint5" type="revolute">
    <parent link="link4"/>
    <child link="link5"/>
    <origin rpy="0.0 0.0 0.0" xyz="0.0 0.15 0.03"/>
    <axis xyz="0 0 1"/>
    <limit effort="1.0" lower="-6.283185307179586" upper="6.283185307179586" velocity="10.0"/>
  </joint>
  <link name="link5">
    <visual name="joint5">
      <origin rpy="0 0 0" xyz="0 0 0"/>
      <geometry>
        <cylinder length="0.03" radius="0.02"/>
      </geometry>
      <material name="grey"/>
    </visual>
    <visual name="link">
      <origin rpy="0 0 0" xyz="0 0 0.05"/>
      <geometry>
        <cylinder length="0.1" radius="0.01"/>
      </geometry>
      <material name="grey"/>
    </visual>
    <visual name="joint6">
      <origin rpy="1.5707963267948966 0 0" xyz="0 0 0.1"/>
      <geometry>
        <cylinder length="0.03" radius="0.02"/>
      </geometry>
      <material name="grey"/>
    </visual>
  </link>
  <joint name="joint6" type="revolute">
    <parent link="link5"/>
    <child link="link6"/>
    <origin rpy="0.0 0.0 0.0" xyz="0.0 0.03 0.1"/>
    <axis xyz="0 1 0"/>
    <limit effort="1.0" lower="-6.283185307179586" upper="6.283185307179586" velocity="10.0"/>
  </joint>
  <link name="link6">
    <visual name="joint6">
      <origin rpy="1.5707963267948966 0 0" xyz="0 0 0"/>
      <geometry>
        <cylinder length="0.03" radius="0.02"/>
      </geometry>
      <material name="grey"/>
    </visual>
    <visual name="link">
      <origin rpy="-1.5707963267948966 0 0" xyz="0 0.025 0"/>
      <geometry>
        <cylinder length="0.05" radius="0.01"/>
      </geometry>
      <material name="grey"/>
    </visual>
  </link>
  <joint name="tool0_joint" type="fixed">
    <origin rpy="0 0 0" xyz="0 0 0.025"/>
    <parent link="sensor_link"/>
    <child link="tool0"/>
  </joint>
  <link name="tool0">
    <visual>
      <origin rpy="0 0 0" xyz="0 0 0"/>
      <geometry>
        <sphere radius="0.01"/>
      </geometry>
      <material name="grey"/>
    </visual>
  </link>
  <!-- Attach a sensor link -->
  <joint name="sensor_link_joint" type="fixed">
    <origin rpy="-1.5707963267948966 0 0" xyz="0 0.025 0"/>
    <parent link="link6"/>
    <child link="sensor_link"/>
  </joint>
  <link name="sensor_link"/>
  <!-- Connect to world -->
  <link name="world"/>
  <joint name="world_joint" type="fixed">
    <parent link="world"/>
    <child link="base_link"/>
    <origin rpy="0.0 0.0 0.0" xyz="0.0 0.0 0.0"/>
  </joint>
</robot>

