<?xml version="1.0" ?>
<!-- =================================================================================== -->
<!-- |    This document was autogenerated by xacro from ur5_3finger.urdf.xacro         | -->
<!-- |    EDITING THIS FILE BY HAND IS NOT RECOMMENDED                                 | -->
<!-- =================================================================================== -->
<robot name="ur5_3finger">
  <gazebo>
    <plugin filename="libgazebo_ros_control.so" name="ros_control">
      <!--robotNamespace>/</robotNamespace-->
      <!--robotSimType>gazebo_ros_control/DefaultRobotHWSim</robotSimType-->
    </plugin>
    <!--
    <plugin name="gazebo_ros_power_monitor_controller" filename="libgazebo_ros_power_monitor.so">
      <alwaysOn>true</alwaysOn>
      <updateRate>1.0</updateRate>
      <timeout>5</timeout>
      <powerStateTopic>power_state</powerStateTopic>
      <powerStateRate>10.0</powerStateRate>
      <fullChargeCapacity>87.78</fullChargeCapacity>     
      <dischargeRate>-474</dischargeRate>
      <chargeRate>525</chargeRate>
      <dischargeVoltage>15.52</dischargeVoltage>
      <chargeVoltage>16.41</chargeVoltage>
    </plugin>
-->
  </gazebo>
  <!-- measured from model -->
  <!--property name="shoulder_height" value="0.089159" /-->
  <!--property name="shoulder_offset" value="0.13585" /-->
  <!-- shoulder_offset - elbow_offset + wrist_1_length = 0.10915 -->
  <!--property name="upper_arm_length" value="0.42500" /-->
  <!--property name="elbow_offset" value="0.1197" /-->
  <!-- CAD measured -->
  <!--property name="forearm_length" value="0.39225" /-->
  <!--property name="wrist_1_length" value="0.093" /-->
  <!-- CAD measured -->
  <!--property name="wrist_2_length" value="0.09465" /-->
  <!-- In CAD this distance is 0.930, but in the spec it is 0.09465 -->
  <!--property name="wrist_3_length" value="0.0823" /-->
  <!-- manually measured -->
  <link name="base_link">
    <visual>
      <geometry>
        <mesh filename="package://ur_description/meshes/ur5/visual/base.dae"/>
      </geometry>
      <material name="LightGrey">
        <color rgba="0.7 0.7 0.7 1.0"/>
      </material>
    </visual>
    <collision>
      <geometry>
        <mesh filename="package://ur_description/meshes/ur5/collision/base.stl"/>
      </geometry>
    </collision>
    <inertial>
      <mass value="4.0"/>
      <origin rpy="0 0 0" xyz="0.0 0.0 0.0"/>
      <inertia ixx="0.00443333156" ixy="0.0" ixz="0.0" iyy="0.00443333156" iyz="0.0" izz="0.0072"/>
    </inertial>
  </link>
  <joint name="shoulder_pan_joint" type="revolute">
    <parent link="base_link"/>
    <child link="shoulder_link"/>
    <origin rpy="0.0 0.0 0.0" xyz="0.0 0.0 0.089159"/>
    <axis xyz="0 0 1"/>
    <limit effort="150.0" lower="-6.283185307179586" upper="6.283185307179586" velocity="3.15"/>
    <dynamics damping="0.0" friction="0.0"/>
  </joint>
  <link name="shoulder_link">
    <visual>
      <geometry>
        <mesh filename="package://ur_description/meshes/ur5/visual/shoulder.dae"/>
      </geometry>
      <material name="LightGrey">
        <color rgba="0.7 0.7 0.7 1.0"/>
      </material>
    </visual>
    <collision>
      <geometry>
        <mesh filename="package://ur_description/meshes/ur5/collision/shoulder.stl"/>
      </geometry>
    </collision>
    <inertial>
      <mass value="3.7"/>
      <origin rpy="0 0 0" xyz="0.0 0.0 0.0"/>
      <inertia ixx="0.010267495893" ixy="0.0" ixz="0.0" iyy="0.010267495893" iyz="0.0" izz="0.00666"/>
    </inertial>
  </link>
  <joint name="shoulder_lift_joint" type="revolute">
    <parent link="shoulder_link"/>
    <child link="upper_arm_link"/>
    <origin rpy="0.0 1.5707963267948966 0.0" xyz="0.0 0.13585 0.0"/>
    <axis xyz="0 1 0"/>
    <limit effort="150.0" lower="-6.283185307179586" upper="6.283185307179586" velocity="3.15"/>
    <dynamics damping="0.0" friction="0.0"/>
  </joint>
  <link name="upper_arm_link">
    <visual>
      <geometry>
        <mesh filename="package://ur_description/meshes/ur5/visual/upperarm.dae"/>
      </geometry>
      <material name="LightGrey">
        <color rgba="0.7 0.7 0.7 1.0"/>
      </material>
    </visual>
    <collision>
      <geometry>
        <mesh filename="package://ur_description/meshes/ur5/collision/upperarm.stl"/>
      </geometry>
    </collision>
    <inertial>
      <mass value="8.393"/>
      <origin rpy="0 0 0" xyz="0.0 0.0 0.28"/>
      <inertia ixx="0.22689067591036005" ixy="0.0" ixz="0.0" iyy="0.22689067591036005" iyz="0.0" izz="0.0151074"/>
    </inertial>
  </link>
  <joint name="elbow_joint" type="revolute">
    <parent link="upper_arm_link"/>
    <child link="forearm_link"/>
    <origin rpy="0.0 0.0 0.0" xyz="0.0 -0.1197 0.425"/>
    <axis xyz="0 1 0"/>
    <limit effort="150.0" lower="-3.141592653589793" upper="3.141592653589793" velocity="3.15"/>
    <dynamics damping="0.0" friction="0.0"/>
  </joint>
  <link name="forearm_link">
    <visual>
      <geometry>
        <mesh filename="package://ur_description/meshes/ur5/visual/forearm.dae"/>
      </geometry>
      <material name="LightGrey">
        <color rgba="0.7 0.7 0.7 1.0"/>
      </material>
    </visual>
    <collision>
      <geometry>
        <mesh filename="package://ur_description/meshes/ur5/collision/forearm.stl"/>
      </geometry>
    </collision>
    <inertial>
      <mass value="2.275"/>
      <origin rpy="0 0 0" xyz="0.0 0.0 0.196125"/>
      <inertia ixx="0.03121679102890359" ixy="0.0" ixz="0.0" iyy="0.03121679102890359" iyz="0.0" izz="0.004095"/>
    </inertial>
  </link>
  <joint name="wrist_1_joint" type="revolute">
    <parent link="forearm_link"/>
    <child link="wrist_1_link"/>
    <origin rpy="0.0 1.5707963267948966 0.0" xyz="0.0 0.0 0.39225"/>
    <axis xyz="0 1 0"/>
    <limit effort="28.0" lower="-6.283185307179586" upper="6.283185307179586" velocity="3.2"/>
    <dynamics damping="0.0" friction="0.0"/>
  </joint>
  <link name="wrist_1_link">
    <visual>
      <geometry>
        <mesh filename="package://ur_description/meshes/ur5/visual/wrist1.dae"/>
      </geometry>
      <material name="LightGrey">
        <color rgba="0.7 0.7 0.7 1.0"/>
      </material>
    </visual>
    <collision>
      <geometry>
        <mesh filename="package://ur_description/meshes/ur5/collision/wrist1.stl"/>
      </geometry>
    </collision>
    <inertial>
      <mass value="1.219"/>
      <origin rpy="0 0 0" xyz="0.0 0.093 0.0"/>
      <inertia ixx="0.0025598989760400002" ixy="0.0" ixz="0.0" iyy="0.0025598989760400002" iyz="0.0" izz="0.0021942"/>
    </inertial>
  </link>
  <joint name="wrist_2_joint" type="revolute">
    <parent link="wrist_1_link"/>
    <child link="wrist_2_link"/>
    <origin rpy="0.0 0.0 0.0" xyz="0.0 0.093 0.0"/>
    <axis xyz="0 0 1"/>
    <limit effort="28.0" lower="-6.283185307179586" upper="6.283185307179586" velocity="3.2"/>
    <dynamics damping="0.0" friction="0.0"/>
  </joint>
  <link name="wrist_2_link">
    <visual>
      <geometry>
        <mesh filename="package://ur_description/meshes/ur5/visual/wrist2.dae"/>
      </geometry>
      <material name="LightGrey">
        <color rgba="0.7 0.7 0.7 1.0"/>
      </material>
    </visual>
    <collision>
      <geometry>
        <mesh filename="package://ur_description/meshes/ur5/collision/wrist2.stl"/>
      </geometry>
    </collision>
    <inertial>
      <mass value="1.219"/>
      <origin rpy="0 0 0" xyz="0.0 0.0 0.09465"/>
      <inertia ixx="0.0025598989760400002" ixy="0.0" ixz="0.0" iyy="0.0025598989760400002" iyz="0.0" izz="0.0021942"/>
    </inertial>
  </link>
  <joint name="wrist_3_joint" type="revolute">
    <parent link="wrist_2_link"/>
    <child link="wrist_3_link"/>
    <origin rpy="0.0 0.0 0.0" xyz="0.0 0.0 0.09465"/>
    <axis xyz="0 1 0"/>
    <limit effort="28.0" lower="-6.283185307179586" upper="6.283185307179586" velocity="3.2"/>
    <dynamics damping="0.0" friction="0.0"/>
  </joint>
  <link name="wrist_3_link">
    <visual>
      <geometry>
        <mesh filename="package://ur_description/meshes/ur5/visual/wrist3.dae"/>
      </geometry>
      <material name="LightGrey">
        <color rgba="0.7 0.7 0.7 1.0"/>
      </material>
    </visual>
    <collision>
      <geometry>
        <mesh filename="package://ur_description/meshes/ur5/collision/wrist3.stl"/>
      </geometry>
    </collision>
    <inertial>
      <mass value="0.1879"/>
      <origin rpy="1.5707963267948966 0 0" xyz="0.0 0.06505 0.0"/>
      <inertia ixx="8.469589112163e-05" ixy="0.0" ixz="0.0" iyy="8.469589112163e-05" iyz="0.0" izz="0.0001321171875"/>
    </inertial>
  </link>
  <joint name="ee_fixed_joint" type="fixed">
    <parent link="wrist_3_link"/>
    <child link="ee_link"/>
    <origin rpy="0.0 0.0 1.5707963267948966" xyz="0.0 0.0823 0.0"/>
  </joint>
  <link name="ee_link">
    <collision>
      <geometry>
        <box size="0.01 0.01 0.01"/>
      </geometry>
      <origin rpy="0 0 0" xyz="-0.01 0 0"/>
    </collision>
  </link>
  <transmission name="shoulder_pan_trans">
    <type>transmission_interface/SimpleTransmission</type>
    <joint name="shoulder_pan_joint">
      <hardwareInterface>hardware_interface/PositionJointInterface</hardwareInterface>
    </joint>
    <actuator name="shoulder_pan_motor">
      <mechanicalReduction>1</mechanicalReduction>
    </actuator>
  </transmission>
  <transmission name="shoulder_lift_trans">
    <type>transmission_interface/SimpleTransmission</type>
    <joint name="shoulder_lift_joint">
      <hardwareInterface>hardware_interface/PositionJointInterface</hardwareInterface>
    </joint>
    <actuator name="shoulder_lift_motor">
      <mechanicalReduction>1</mechanicalReduction>
    </actuator>
  </transmission>
  <transmission name="elbow_trans">
    <type>transmission_interface/SimpleTransmission</type>
    <joint name="elbow_joint">
      <hardwareInterface>hardware_interface/PositionJointInterface</hardwareInterface>
    </joint>
    <actuator name="elbow_motor">
      <mechanicalReduction>1</mechanicalReduction>
    </actuator>
  </transmission>
  <transmission name="wrist_1_trans">
    <type>transmission_interface/SimpleTransmission</type>
    <joint name="wrist_1_joint">
      <hardwareInterface>hardware_interface/PositionJointInterface</hardwareInterface>
    </joint>
    <actuator name="wrist_1_motor">
      <mechanicalReduction>1</mechanicalReduction>
    </actuator>
  </transmission>
  <transmission name="wrist_2_trans">
    <type>transmission_interface/SimpleTransmission</type>
    <joint name="wrist_2_joint">
      <hardwareInterface>hardware_interface/PositionJointInterface</hardwareInterface>
    </joint>
    <actuator name="wrist_2_motor">
      <mechanicalReduction>1</mechanicalReduction>
    </actuator>
  </transmission>
  <transmission name="wrist_3_trans">
    <type>transmission_interface/SimpleTransmission</type>
    <joint name="wrist_3_joint">
      <hardwareInterface>hardware_interface/PositionJointInterface</hardwareInterface>
    </joint>
    <actuator name="wrist_3_motor">
      <mechanicalReduction>1</mechanicalReduction>
    </actuator>
  </transmission>
  <gazebo reference="shoulder_link">
    <selfCollide>true</selfCollide>
  </gazebo>
  <gazebo reference="upper_arm_link">
    <selfCollide>true</selfCollide>
  </gazebo>
  <gazebo reference="forearm_link">
    <selfCollide>true</selfCollide>
  </gazebo>
  <gazebo reference="wrist_1_link">
    <selfCollide>true</selfCollide>
  </gazebo>
  <gazebo reference="wrist_3_link">
    <selfCollide>true</selfCollide>
  </gazebo>
  <gazebo reference="wrist_2_link">
    <selfCollide>true</selfCollide>
  </gazebo>
  <gazebo reference="ee_link">
    <selfCollide>true</selfCollide>
  </gazebo>
  <!-- ROS base_link to UR 'Base' Coordinates transform -->
  <link name="base"/>
  <joint name="base_link-base_fixed_joint" type="fixed">
    <!-- NOTE: this rotation is only needed as long as base_link itself is
                 not corrected wrt the real robot (ie: rotated over 180
                 degrees)
      -->
    <origin rpy="0 0 -3.141592653589793" xyz="0 0 0"/>
    <parent link="base_link"/>
    <child link="base"/>
  </joint>
  <!-- Frame coincident with all-zeros TCP on UR controller -->
  <link name="tool0"/>
  <joint name="wrist_3_link-tool0_fixed_joint" type="fixed">
    <origin rpy="-1.5707963267948966 0 0" xyz="0 0.0823 0"/>
    <parent link="wrist_3_link"/>
    <child link="tool0"/>
  </joint>
  <link name="H1_base_attach"/>
  <material name="Blue">
    <color rgba="0.0 0.0 0.8 1.0"/>
  </material>
  <material name="Green">
    <color rgba="0.0 0.8 0.0 1.0"/>
  </material>
  <material name="BiotacGreen">
    <color rgba="0.31 0.85 0.42 1.0"/>
  </material>
  <material name="Grey">
    <color rgba="0.2 0.2 0.2 1.0"/>
  </material>
  <material name="LightGrey">
    <color rgba="0.6 0.6 0.6 1.0"/>
  </material>
  <material name="Red">
    <color rgba="0.8 0.0 0.0 1.0"/>
  </material>
  <material name="White">
    <color rgba="1.0 1.0 1.0 1.0"/>
  </material>
  <link name="H1_base_link">
    <inertial>
      <origin rpy="0 0 0" xyz="-8.6116E-06 -0.0058125 0.028294"/>
      <mass value="0.07527"/>
      <inertia ixx="0.00014442" ixy="1.2033E-08" ixz="-5.9646E-10" iyy="0.00014979" iyz="-1.0288E-05" izz="5.2943E-05"/>
    </inertial>
    <visual>
      <origin rpy="0 0 0" xyz="0 0 0"/>
      <geometry>
        <mesh filename="package://ur5_data_collect_fw/meshes/gripper/3finger/palm_link_simple.dae"/>
      </geometry>
      <material name="light_grey">
        <color rgba="0.75 0.75 0.75 1.0"/>
      </material>
    </visual>
    <collision>
      <origin rpy="0 0 0" xyz="0 0 0"/>
      <geometry>
        <mesh filename="package://ur5_data_collect_fw/meshes/gripper/3finger/palm_link_simple.dae"/>
      </geometry>
      <material name="light_grey">
        <color rgba="0.75 0.75 0.75 1.0"/>
      </material>
    </collision>
  </link>
  <joint name="H1Base" type="fixed">
    <origin rpy="0 0 0" xyz="0 0 0"/>
    <parent link="H1_base_attach"/>
    <child link="H1_wrist_attach"/>
  </joint>
  <gazebo>
    <plugin filename="libgazebo_ros_imu.so" name="imu_controller">
      <alwaysOn>true</alwaysOn>
      <updateRate>50</updateRate>
      <bodyName>H1_base_link</bodyName>
      <!--imu_link -->
      <topicName>imu/data</topicName>
      <serviceName>imu/is_calibrated</serviceName>
      <gaussianNoise>2.89e-08</gaussianNoise>
      <xyzOffsets>0 0 0</xyzOffsets>
      <rpyOffsets>0 0 0</rpyOffsets>
    </plugin>
  </gazebo>
  <link name="H1_insert_F1"/>
  <joint name="H1_dummy_joint_1" type="fixed">
    <origin rpy="0 0 2.3562" xyz="-0.045 -0.025981 0"/>
    <axis xyz="0 -1 0"/>
    <parent link="H1_base_link"/>
    <child link="H1_insert_F1"/>
  </joint>
  <link name="H1_insert_F2"/>
  <joint name="H1_dummy_joint_2" type="fixed">
    <origin rpy="0 0 0" xyz="0 0.029019 0"/>
    <axis xyz="0 -1 0"/>
    <parent link="H1_base_link"/>
    <child link="H1_insert_F2"/>
  </joint>
  <link name="H1_insert_F3"/>
  <joint name="H1_dummy_joint_3" type="fixed">
    <origin rpy="0 0 -2.3562" xyz="0.045 -0.025981 0"/>
    <axis xyz="0 -1 0"/>
    <parent link="H1_base_link"/>
    <child link="H1_insert_F3"/>
  </joint>
  <link name="H1_wrist_attach"/>
  <joint name="H1_base_link_wrist_attach" type="fixed">
    <origin rpy="0 0 0" xyz="0 0 -0.0005"/>
    <child link="H1_base_link"/>
    <parent link="H1_wrist_attach"/>
  </joint>
  <link name="H1_F1_palm_link">
    <inertial>
      <origin rpy="0 0 0" xyz="-0.00681802120880393 -0.00947020456878004 0.067587996682422"/>
      <mass value="0.0341482312344481"/>
      <inertia ixx="2.79747833772125E-05" ixy="-5.50900644725373E-08" ixz="-2.82072424927723E-07" iyy="2.67800858812928E-05" iyz="3.1953125069394E-06" izz="9.86122271726361E-06"/>
    </inertial>
    <visual>
      <origin rpy="0 0 0" xyz="0 0 0"/>
      <geometry>
        <mesh filename="package://ur5_data_collect_fw/meshes/gripper/3finger/finger_palm_link.dae"/>
      </geometry>
      <material name="light_grey">
        <color rgba="0.75 0.75 0.75 1.0"/>
      </material>
    </visual>
    <!-- Collision mesh no needed as it is part of palm_link_simple.dae collision mesh -->
    <!--xacro:mesh_collision file_name="v2/finger_palm_link.dae">
        <origin xyz="0 0 0" rpy="0 0 0" />
        <xacro:light_grey/>
      </xacro:mesh_collision-->
  </link>
  <link name="H1_F1_base_link">
    <inertial>
      <origin rpy="0 0 0" xyz="-0.000142856770000038 0.0265691681336443 0.0538751581621436"/>
      <mass value="0.174652229503358"/>
      <inertia ixx="0.000298372741514267" ixy="-5.05751882577435E-07" ixz="1.94982779411417E-07" iyy="0.000299629589232877" iyz="2.79565205733806E-05" izz="0.000134889645145365"/>
    </inertial>
    <visual>
      <origin rpy="0 0 0" xyz="0 0 0"/>
      <geometry>
        <mesh filename="package://ur5_data_collect_fw/meshes/gripper/3finger/finger_base_link_simple.dae"/>
      </geometry>
      <material name="light_grey">
        <color rgba="0.75 0.75 0.75 1.0"/>
      </material>
    </visual>
    <collision>
      <origin rpy="0 0 0" xyz="0 0 0"/>
      <geometry>
        <mesh filename="package://ur5_data_collect_fw/meshes/gripper/3finger/finger_base_link_simple.dae"/>
      </geometry>
      <material name="light_grey">
        <color rgba="0.75 0.75 0.75 1.0"/>
      </material>
    </collision>
  </link>
  <link name="H1_F1_link_1">
    <inertial>
      <origin rpy="0 0 0" xyz="-0.000141876508729455 -0.00135409566494088 0.0277606215980989"/>
      <mass value="0.0827759744227546"/>
      <inertia ixx="4.61070151157777E-05" ixy="7.47741111557837E-08" ixz="-2.25165057702697E-07" iyy="5.27678327317508E-05" iyz="-3.64603343546298E-07" izz="2.89599551320955E-05"/>
    </inertial>
    <visual>
      <origin rpy="0 0 0" xyz="0 0 0"/>
      <geometry>
        <mesh filename="package://ur5_data_collect_fw/meshes/gripper/3finger/finger_prox_link_simple.dae"/>
      </geometry>
      <material name="light_grey">
        <color rgba="0.75 0.75 0.75 1.0"/>
      </material>
    </visual>
    <collision>
      <origin rpy="0 0 0" xyz="0 0 0"/>
      <geometry>
        <mesh filename="package://ur5_data_collect_fw/meshes/gripper/3finger/finger_prox_link_simple.dae"/>
      </geometry>
      <material name="light_grey">
        <color rgba="0.75 0.75 0.75 1.0"/>
      </material>
    </collision>
  </link>
  <link name="H1_F1_link_2">
    <inertial>
      <origin rpy="0 0 0" xyz="0.000506812071918918 -0.00091292934992606 0.0156620851768385"/>
      <mass value="0.0270049614151599"/>
      <inertia ixx="1.06942730265546E-05" ixy="-7.1810089794211E-09" ixz="-3.49957211410822E-07" iyy="1.05772889540593E-05" iyz="-8.38595987731518E-07" izz="3.27173446995846E-06"/>
    </inertial>
    <visual>
      <origin rpy="0 0 0" xyz="0 0 0"/>
      <geometry>
        <mesh filename="package://ur5_data_collect_fw/meshes/gripper/3finger/finger_dist_link_simple.dae"/>
      </geometry>
      <material name="light_grey">
        <color rgba="0.75 0.75 0.75 1.0"/>
      </material>
    </visual>
    <collision>
      <origin rpy="0 0 0" xyz="0 0 0"/>
      <geometry>
        <mesh filename="package://ur5_data_collect_fw/meshes/gripper/3finger/finger_dist_link_simple.dae"/>
      </geometry>
      <material name="light_grey">
        <color rgba="0.75 0.75 0.75 1.0"/>
      </material>
    </collision>
  </link>
  <joint name="H1_F1Palm" type="fixed">
    <origin rpy="0 0 0" xyz="0 0 0"/>
    <parent link="H1_insert_F1"/>
    <child link="H1_F1_palm_link"/>
  </joint>
  <joint name="H1_F1J1" type="revolute">
    <origin rpy="-8.8818E-16 -1.0061E-16 0.022402" xyz="0 0 0.00016528"/>
    <axis xyz="0 0 1"/>
    <parent link="H1_F1_palm_link"/>
    <child link="H1_F1_base_link"/>
    <limit effort="50" lower="-0.785398163397" upper="0.785398163397" velocity="1.0"/>
    <dynamics damping="0.0" friction="0.0"/>
  </joint>
  <joint name="H1_F1J2" type="revolute">
    <origin rpy="0.070695 6.9389E-16 2.0947E-16" xyz="0 0.035 0.11683"/>
    <axis xyz="1 0 0"/>
    <parent link="H1_F1_base_link"/>
    <child link="H1_F1_link_1"/>
    <limit effort="50" lower="-1.3962634016" upper="1.0471975512" velocity="1.0"/>
    <dynamics damping="0.0" friction="0.0"/>
  </joint>
  <joint name="H1_F1J3" type="revolute">
    <origin rpy="-0.0068649 1.7347E-18 1.6176E-16" xyz="0 0 0.06"/>
    <axis xyz="1 0 0"/>
    <parent link="H1_F1_link_1"/>
    <child link="H1_F1_link_2"/>
    <limit effort="50" lower="-1.0471975512" upper="1.57079632679" velocity="1.0"/>
    <dynamics damping="0.0" friction="0.0"/>
  </joint>
  <transmission name="H1_F1J1_transmission">
    <type>transmission_interface/SimpleTransmission</type>
    <actuator name="H1_F1J1">
      <mechanicalReduction>1</mechanicalReduction>
    </actuator>
    <joint name="H1_F1J1">
      <hardwareInterface>hardware_interface/PositionJointInterface</hardwareInterface>
    </joint>
  </transmission>
  <transmission name="H1_F1J2_transmission">
    <type>transmission_interface/SimpleTransmission</type>
    <actuator name="H1_F1J2">
      <mechanicalReduction>1</mechanicalReduction>
    </actuator>
    <joint name="H1_F1J2">
      <hardwareInterface>hardware_interface/PositionJointInterface</hardwareInterface>
    </joint>
  </transmission>
  <transmission name="H1_F1J3_transmission">
    <type>transmission_interface/SimpleTransmission</type>
    <actuator name="H1_F1J3">
      <mechanicalReduction>1</mechanicalReduction>
    </actuator>
    <joint name="H1_F1J3">
      <hardwareInterface>hardware_interface/PositionJointInterface</hardwareInterface>
    </joint>
  </transmission>
  <!-- finger tip -->
  <link name="H1_F1_tip">
    <inertial>
      <origin rpy="0 0 0" xyz="-0.000925580990320645 -0.00495543398528436 0.0355865585792753"/>
      <mass value="0.00906322686585137"/>
      <inertia ixx="1.10049088227995E-06" ixy="-3.7290982171096E-09" ixz="-9.54389365908683E-09" iyy="1.36130530510584E-06" iyz="6.66133713720777E-08" izz="6.42259773618367E-07"/>
    </inertial>
    <visual>
      <origin rpy="0 0 0" xyz="0 0 0"/>
      <geometry>
        <mesh filename="package://ur5_data_collect_fw/meshes/gripper/3finger/omd-d18-tip.dae"/>
      </geometry>
      <material name="light_grey">
        <color rgba="0.75 0.75 0.75 1.0"/>
      </material>
    </visual>
    <collision>
      <origin rpy="0 0 0" xyz="0 0 0"/>
      <geometry>
        <mesh filename="package://ur5_data_collect_fw/meshes/gripper/3finger/omd-d18-tip.dae"/>
      </geometry>
      <material name="light_grey">
        <color rgba="0.75 0.75 0.75 1.0"/>
      </material>
    </collision>
  </link>
  <link name="H1_F1_optoforce"/>
  <joint name="H1_F1_tip_to_optoforce" type="fixed">
    <parent link="H1_F1_tip"/>
    <child link="H1_F1_optoforce"/>
    <origin rpy="-0.35 0 0" xyz="0 -0.006 0.046"/>
  </joint>
  <joint name="H1_F1_tip" type="fixed">
    <parent link="H1_F1_link_2"/>
    <child link="H1_F1_tip"/>
  </joint>
  <link name="H1_F2_palm_link">
    <inertial>
      <origin rpy="0 0 0" xyz="-0.00681802120880393 -0.00947020456878004 0.067587996682422"/>
      <mass value="0.0341482312344481"/>
      <inertia ixx="2.79747833772125E-05" ixy="-5.50900644725373E-08" ixz="-2.82072424927723E-07" iyy="2.67800858812928E-05" iyz="3.1953125069394E-06" izz="9.86122271726361E-06"/>
    </inertial>
    <visual>
      <origin rpy="0 0 0" xyz="0 0 0"/>
      <geometry>
        <mesh filename="package://ur5_data_collect_fw/meshes/gripper/3finger/finger_palm_link.dae"/>
      </geometry>
      <material name="light_grey">
        <color rgba="0.75 0.75 0.75 1.0"/>
      </material>
    </visual>
    <!-- Collision mesh no needed as it is part of palm_link_simple.dae collision mesh -->
    <!--xacro:mesh_collision file_name="v2/finger_palm_link.dae">
        <origin xyz="0 0 0" rpy="0 0 0" />
        <xacro:light_grey/>
      </xacro:mesh_collision-->
  </link>
  <link name="H1_F2_base_link">
    <inertial>
      <origin rpy="0 0 0" xyz="-0.000142856770000038 0.0265691681336443 0.0538751581621436"/>
      <mass value="0.174652229503358"/>
      <inertia ixx="0.000298372741514267" ixy="-5.05751882577435E-07" ixz="1.94982779411417E-07" iyy="0.000299629589232877" iyz="2.79565205733806E-05" izz="0.000134889645145365"/>
    </inertial>
    <visual>
      <origin rpy="0 0 0" xyz="0 0 0"/>
      <geometry>
        <mesh filename="package://ur5_data_collect_fw/meshes/gripper/3finger/finger_base_link_simple.dae"/>
      </geometry>
      <material name="light_grey">
        <color rgba="0.75 0.75 0.75 1.0"/>
      </material>
    </visual>
    <collision>
      <origin rpy="0 0 0" xyz="0 0 0"/>
      <geometry>
        <mesh filename="package://ur5_data_collect_fw/meshes/gripper/3finger/finger_base_link_simple.dae"/>
      </geometry>
      <material name="light_grey">
        <color rgba="0.75 0.75 0.75 1.0"/>
      </material>
    </collision>
  </link>
  <link name="H1_F2_link_1">
    <inertial>
      <origin rpy="0 0 0" xyz="-0.000141876508729455 -0.00135409566494088 0.0277606215980989"/>
      <mass value="0.0827759744227546"/>
      <inertia ixx="4.61070151157777E-05" ixy="7.47741111557837E-08" ixz="-2.25165057702697E-07" iyy="5.27678327317508E-05" iyz="-3.64603343546298E-07" izz="2.89599551320955E-05"/>
    </inertial>
    <visual>
      <origin rpy="0 0 0" xyz="0 0 0"/>
      <geometry>
        <mesh filename="package://ur5_data_collect_fw/meshes/gripper/3finger/finger_prox_link_simple.dae"/>
      </geometry>
      <material name="light_grey">
        <color rgba="0.75 0.75 0.75 1.0"/>
      </material>
    </visual>
    <collision>
      <origin rpy="0 0 0" xyz="0 0 0"/>
      <geometry>
        <mesh filename="package://ur5_data_collect_fw/meshes/gripper/3finger/finger_prox_link_simple.dae"/>
      </geometry>
      <material name="light_grey">
        <color rgba="0.75 0.75 0.75 1.0"/>
      </material>
    </collision>
  </link>
  <link name="H1_F2_link_2">
    <inertial>
      <origin rpy="0 0 0" xyz="0.000506812071918918 -0.00091292934992606 0.0156620851768385"/>
      <mass value="0.0270049614151599"/>
      <inertia ixx="1.06942730265546E-05" ixy="-7.1810089794211E-09" ixz="-3.49957211410822E-07" iyy="1.05772889540593E-05" iyz="-8.38595987731518E-07" izz="3.27173446995846E-06"/>
    </inertial>
    <visual>
      <origin rpy="0 0 0" xyz="0 0 0"/>
      <geometry>
        <mesh filename="package://ur5_data_collect_fw/meshes/gripper/3finger/finger_dist_link_simple.dae"/>
      </geometry>
      <material name="light_grey">
        <color rgba="0.75 0.75 0.75 1.0"/>
      </material>
    </visual>
    <collision>
      <origin rpy="0 0 0" xyz="0 0 0"/>
      <geometry>
        <mesh filename="package://ur5_data_collect_fw/meshes/gripper/3finger/finger_dist_link_simple.dae"/>
      </geometry>
      <material name="light_grey">
        <color rgba="0.75 0.75 0.75 1.0"/>
      </material>
    </collision>
  </link>
  <joint name="H1_F2Palm" type="fixed">
    <origin rpy="0 0 0" xyz="0 0 0"/>
    <parent link="H1_insert_F2"/>
    <child link="H1_F2_palm_link"/>
  </joint>
  <joint name="H1_F2J1" type="revolute">
    <origin rpy="-8.8818E-16 -1.0061E-16 0.022402" xyz="0 0 0.00016528"/>
    <axis xyz="0 0 1"/>
    <parent link="H1_F2_palm_link"/>
    <child link="H1_F2_base_link"/>
    <limit effort="30" lower="-0.785398163397" upper="0.785398163397" velocity="1.0"/>
    <dynamics damping="0.0" friction="0.0"/>
  </joint>
  <joint name="H1_F2J2" type="revolute">
    <origin rpy="0.070695 6.9389E-16 2.0947E-16" xyz="0 0.035 0.11683"/>
    <axis xyz="1 0 0"/>
    <parent link="H1_F2_base_link"/>
    <child link="H1_F2_link_1"/>
    <limit effort="30" lower="-1.3962634016" upper="1.0471975512" velocity="1.0"/>
    <dynamics damping="0.0" friction="0.0"/>
  </joint>
  <joint name="H1_F2J3" type="revolute">
    <origin rpy="-0.0068649 1.7347E-18 1.6176E-16" xyz="0 0 0.06"/>
    <axis xyz="1 0 0"/>
    <parent link="H1_F2_link_1"/>
    <child link="H1_F2_link_2"/>
    <limit effort="30" lower="-1.0471975512" upper="1.57079632679" velocity="1.0"/>
    <dynamics damping="0.0" friction="0.0"/>
  </joint>
  <transmission name="H1_F2J1_transmission">
    <type>transmission_interface/SimpleTransmission</type>
    <actuator name="H1_F2J1">
      <mechanicalReduction>1</mechanicalReduction>
    </actuator>
    <joint name="H1_F2J1">
      <hardwareInterface>hardware_interface/PositionJointInterface</hardwareInterface>
    </joint>
  </transmission>
  <transmission name="H1_F2J2_transmission">
    <type>transmission_interface/SimpleTransmission</type>
    <actuator name="H1_F2J2">
      <mechanicalReduction>1</mechanicalReduction>
    </actuator>
    <joint name="H1_F2J2">
      <hardwareInterface>hardware_interface/PositionJointInterface</hardwareInterface>
    </joint>
  </transmission>
  <transmission name="H1_F2J3_transmission">
    <type>transmission_interface/SimpleTransmission</type>
    <actuator name="H1_F2J3">
      <mechanicalReduction>1</mechanicalReduction>
    </actuator>
    <joint name="H1_F2J3">
      <hardwareInterface>hardware_interface/PositionJointInterface</hardwareInterface>
    </joint>
  </transmission>
  <!-- finger tip -->
  <link name="H1_F2_tip">
    <inertial>
      <origin rpy="0 0 0" xyz="-0.000925580990320645 -0.00495543398528436 0.0355865585792753"/>
      <mass value="0.00906322686585137"/>
      <inertia ixx="1.10049088227995E-06" ixy="-3.7290982171096E-09" ixz="-9.54389365908683E-09" iyy="1.36130530510584E-06" iyz="6.66133713720777E-08" izz="6.42259773618367E-07"/>
    </inertial>
    <visual>
      <origin rpy="0 0 0" xyz="0 0 0"/>
      <geometry>
        <mesh filename="package://ur5_data_collect_fw/meshes/gripper/3finger/omd-d18-tip.dae"/>
      </geometry>
      <material name="light_grey">
        <color rgba="0.75 0.75 0.75 1.0"/>
      </material>
    </visual>
    <collision>
      <origin rpy="0 0 0" xyz="0 0 0"/>
      <geometry>
        <mesh filename="package://ur5_data_collect_fw/meshes/gripper/3finger/omd-d18-tip.dae"/>
      </geometry>
      <material name="light_grey">
        <color rgba="0.75 0.75 0.75 1.0"/>
      </material>
    </collision>
  </link>
  <link name="H1_F2_optoforce"/>
  <joint name="H1_F2_tip_to_optoforce" type="fixed">
    <parent link="H1_F2_tip"/>
    <child link="H1_F2_optoforce"/>
    <origin rpy="-0.35 0 0" xyz="0 -0.006 0.046"/>
  </joint>
  <joint name="H1_F2_tip" type="fixed">
    <parent link="H1_F2_link_2"/>
    <child link="H1_F2_tip"/>
  </joint>
  <link name="H1_F3_palm_link">
    <inertial>
      <origin rpy="0 0 0" xyz="-0.00681802120880393 -0.00947020456878004 0.067587996682422"/>
      <mass value="0.0341482312344481"/>
      <inertia ixx="2.79747833772125E-05" ixy="-5.50900644725373E-08" ixz="-2.82072424927723E-07" iyy="2.67800858812928E-05" iyz="3.1953125069394E-06" izz="9.86122271726361E-06"/>
    </inertial>
    <visual>
      <origin rpy="0 0 0" xyz="0 0 0"/>
      <geometry>
        <mesh filename="package://ur5_data_collect_fw/meshes/gripper/3finger/finger_palm_link.dae"/>
      </geometry>
      <material name="light_grey">
        <color rgba="0.75 0.75 0.75 1.0"/>
      </material>
    </visual>
    <!-- Collision mesh no needed as it is part of palm_link_simple.dae collision mesh -->
    <!--xacro:mesh_collision file_name="v2/finger_palm_link.dae">
        <origin xyz="0 0 0" rpy="0 0 0" />
        <xacro:light_grey/>
      </xacro:mesh_collision-->
  </link>
  <link name="H1_F3_base_link">
    <inertial>
      <origin rpy="0 0 0" xyz="-0.000142856770000038 0.0265691681336443 0.0538751581621436"/>
      <mass value="0.174652229503358"/>
      <inertia ixx="0.000298372741514267" ixy="-5.05751882577435E-07" ixz="1.94982779411417E-07" iyy="0.000299629589232877" iyz="2.79565205733806E-05" izz="0.000134889645145365"/>
    </inertial>
    <visual>
      <origin rpy="0 0 0" xyz="0 0 0"/>
      <geometry>
        <mesh filename="package://ur5_data_collect_fw/meshes/gripper/3finger/finger_base_link_simple.dae"/>
      </geometry>
      <material name="light_grey">
        <color rgba="0.75 0.75 0.75 1.0"/>
      </material>
    </visual>
    <collision>
      <origin rpy="0 0 0" xyz="0 0 0"/>
      <geometry>
        <mesh filename="package://ur5_data_collect_fw/meshes/gripper/3finger/finger_base_link_simple.dae"/>
      </geometry>
      <material name="light_grey">
        <color rgba="0.75 0.75 0.75 1.0"/>
      </material>
    </collision>
  </link>
  <link name="H1_F3_link_1">
    <inertial>
      <origin rpy="0 0 0" xyz="-0.000141876508729455 -0.00135409566494088 0.0277606215980989"/>
      <mass value="0.0827759744227546"/>
      <inertia ixx="4.61070151157777E-05" ixy="7.47741111557837E-08" ixz="-2.25165057702697E-07" iyy="5.27678327317508E-05" iyz="-3.64603343546298E-07" izz="2.89599551320955E-05"/>
    </inertial>
    <visual>
      <origin rpy="0 0 0" xyz="0 0 0"/>
      <geometry>
        <mesh filename="package://ur5_data_collect_fw/meshes/gripper/3finger/finger_prox_link_simple.dae"/>
      </geometry>
      <material name="light_grey">
        <color rgba="0.75 0.75 0.75 1.0"/>
      </material>
    </visual>
    <collision>
      <origin rpy="0 0 0" xyz="0 0 0"/>
      <geometry>
        <mesh filename="package://ur5_data_collect_fw/meshes/gripper/3finger/finger_prox_link_simple.dae"/>
      </geometry>
      <material name="light_grey">
        <color rgba="0.75 0.75 0.75 1.0"/>
      </material>
    </collision>
  </link>
  <link name="H1_F3_link_2">
    <inertial>
      <origin rpy="0 0 0" xyz="0.000506812071918918 -0.00091292934992606 0.0156620851768385"/>
      <mass value="0.0270049614151599"/>
      <inertia ixx="1.06942730265546E-05" ixy="-7.1810089794211E-09" ixz="-3.49957211410822E-07" iyy="1.05772889540593E-05" iyz="-8.38595987731518E-07" izz="3.27173446995846E-06"/>
    </inertial>
    <visual>
      <origin rpy="0 0 0" xyz="0 0 0"/>
      <geometry>
        <mesh filename="package://ur5_data_collect_fw/meshes/gripper/3finger/finger_dist_link_simple.dae"/>
      </geometry>
      <material name="light_grey">
        <color rgba="0.75 0.75 0.75 1.0"/>
      </material>
    </visual>
    <collision>
      <origin rpy="0 0 0" xyz="0 0 0"/>
      <geometry>
        <mesh filename="package://ur5_data_collect_fw/meshes/gripper/3finger/finger_dist_link_simple.dae"/>
      </geometry>
      <material name="light_grey">
        <color rgba="0.75 0.75 0.75 1.0"/>
      </material>
    </collision>
  </link>
  <joint name="H1_F3Palm" type="fixed">
    <origin rpy="0 0 0" xyz="0 0 0"/>
    <parent link="H1_insert_F3"/>
    <child link="H1_F3_palm_link"/>
  </joint>
  <joint name="H1_F3J1" type="revolute">
    <origin rpy="-8.8818E-16 -1.0061E-16 0.022402" xyz="0 0 0.00016528"/>
    <axis xyz="0 0 1"/>
    <parent link="H1_F3_palm_link"/>
    <child link="H1_F3_base_link"/>
    <limit effort="30" lower="-0.785398163397" upper="0.785398163397" velocity="1.0"/>
    <dynamics damping="0.0" friction="0.0"/>
  </joint>
  <joint name="H1_F3J2" type="revolute">
    <origin rpy="0.070695 6.9389E-16 2.0947E-16" xyz="0 0.035 0.11683"/>
    <axis xyz="1 0 0"/>
    <parent link="H1_F3_base_link"/>
    <child link="H1_F3_link_1"/>
    <limit effort="30" lower="-1.3962634016" upper="1.0471975512" velocity="1.0"/>
    <dynamics damping="0.0" friction="0.0"/>
  </joint>
  <joint name="H1_F3J3" type="revolute">
    <origin rpy="-0.0068649 1.7347E-18 1.6176E-16" xyz="0 0 0.06"/>
    <axis xyz="1 0 0"/>
    <parent link="H1_F3_link_1"/>
    <child link="H1_F3_link_2"/>
    <limit effort="30" lower="-1.0471975512" upper="1.57079632679" velocity="1.0"/>
    <dynamics damping="0.0" friction="0.0"/>
  </joint>
  <transmission name="H1_F3J1_transmission">
    <type>transmission_interface/SimpleTransmission</type>
    <actuator name="H1_F3J1">
      <mechanicalReduction>1</mechanicalReduction>
    </actuator>
    <joint name="H1_F3J1">
      <hardwareInterface>hardware_interface/PositionJointInterface</hardwareInterface>
    </joint>
  </transmission>
  <transmission name="H1_F3J2_transmission">
    <type>transmission_interface/SimpleTransmission</type>
    <actuator name="H1_F3J2">
      <mechanicalReduction>1</mechanicalReduction>
    </actuator>
    <joint name="H1_F3J2">
      <hardwareInterface>hardware_interface/PositionJointInterface</hardwareInterface>
    </joint>
  </transmission>
  <transmission name="H1_F3J3_transmission">
    <type>transmission_interface/SimpleTransmission</type>
    <actuator name="H1_F3J3">
      <mechanicalReduction>1</mechanicalReduction>
    </actuator>
    <joint name="H1_F3J3">
      <hardwareInterface>hardware_interface/PositionJointInterface</hardwareInterface>
    </joint>
  </transmission>
  <!-- finger tip -->
  <link name="H1_F3_tip">
    <inertial>
      <origin rpy="0 0 0" xyz="-0.000925580990320645 -0.00495543398528436 0.0355865585792753"/>
      <mass value="0.00906322686585137"/>
      <inertia ixx="1.10049088227995E-06" ixy="-3.7290982171096E-09" ixz="-9.54389365908683E-09" iyy="1.36130530510584E-06" iyz="6.66133713720777E-08" izz="6.42259773618367E-07"/>
    </inertial>
    <visual>
      <origin rpy="0 0 0" xyz="0 0 0"/>
      <geometry>
        <mesh filename="package://ur5_data_collect_fw/meshes/gripper/3finger/omd-d18-tip.dae"/>
      </geometry>
      <material name="light_grey">
        <color rgba="0.75 0.75 0.75 1.0"/>
      </material>
    </visual>
    <collision>
      <origin rpy="0 0 0" xyz="0 0 0"/>
      <geometry>
        <mesh filename="package://ur5_data_collect_fw/meshes/gripper/3finger/omd-d18-tip.dae"/>
      </geometry>
      <material name="light_grey">
        <color rgba="0.75 0.75 0.75 1.0"/>
      </material>
    </collision>
  </link>
  <link name="H1_F3_optoforce"/>
  <joint name="H1_F3_tip_to_optoforce" type="fixed">
    <parent link="H1_F3_tip"/>
    <child link="H1_F3_optoforce"/>
    <origin rpy="-0.35 0 0" xyz="0 -0.006 0.046"/>
  </joint>
  <joint name="H1_F3_tip" type="fixed">
    <parent link="H1_F3_link_2"/>
    <child link="H1_F3_tip"/>
  </joint>
  <joint name="arm_to_hand" type="fixed">
    <parent link="ee_link"/>
    <child link="H1_base_attach"/>
    <origin rpy="1.57079632679 3.14159265359 1.57079632679" xyz="0.01 0.0 0.0"/>
  </joint>
  <gazebo reference="H1_F1J1">
    <implicitSpringDamper>1</implicitSpringDamper>
  </gazebo>
  <gazebo reference="H1_F1J2">
    <implicitSpringDamper>1</implicitSpringDamper>
  </gazebo>
  <gazebo reference="H1_F1J3">
    <implicitSpringDamper>1</implicitSpringDamper>
  </gazebo>
  <gazebo reference="H1_F2J1">
    <implicitSpringDamper>1</implicitSpringDamper>
  </gazebo>
  <gazebo reference="H1_F2J2">
    <implicitSpringDamper>1</implicitSpringDamper>
  </gazebo>
  <gazebo reference="H1_F2J3">
    <implicitSpringDamper>1</implicitSpringDamper>
  </gazebo>
  <gazebo reference="H1_F3J1">
    <implicitSpringDamper>1</implicitSpringDamper>
  </gazebo>
  <gazebo reference="H1_F3J2">
    <implicitSpringDamper>1</implicitSpringDamper>
  </gazebo>
  <gazebo reference="H1_F3J3">
    <implicitSpringDamper>1</implicitSpringDamper>
  </gazebo>
  <gazebo reference="H1_F1_link_1">
    <kp>1000000.0</kp>
    <kd>100.0</kd>
    <mu1>1.5</mu1>
    <mu2>1.5</mu2>
    <fdir1>1 0 0</fdir1>
    <maxVel>1.0</maxVel>
    <minDepth>0.002</minDepth>
    <material>Gazebo/DarkGrey</material>
  </gazebo>
  <gazebo reference="H1_F1_link_2">
    <kp>1000000.0</kp>
    <kd>100.0</kd>
    <mu1>1.5</mu1>
    <mu2>1.5</mu2>
    <fdir1>1 0 0</fdir1>
    <maxVel>1.0</maxVel>
    <minDepth>0.002</minDepth>
    <material>Gazebo/DarkGrey</material>
  </gazebo>
  <gazebo reference="H1_F1_tip">
    <kp>1000000.0</kp>
    <kd>100.0</kd>
    <mu1>1.5</mu1>
    <mu2>1.5</mu2>
    <fdir1>1 0 0</fdir1>
    <maxVel>1.0</maxVel>
    <minDepth>0.002</minDepth>
    <material>Gazebo/DarkGrey</material>
  </gazebo>
  <gazebo reference="H1_F2_link_1">
    <kp>1000000.0</kp>
    <kd>100.0</kd>
    <mu1>1.5</mu1>
    <mu2>1.5</mu2>
    <fdir1>1 0 0</fdir1>
    <maxVel>1.0</maxVel>
    <minDepth>0.002</minDepth>
    <material>Gazebo/DarkGrey</material>
  </gazebo>
  <gazebo reference="H1_F2_link_2">
    <kp>1000000.0</kp>
    <kd>100.0</kd>
    <mu1>1.5</mu1>
    <mu2>1.5</mu2>
    <fdir1>1 0 0</fdir1>
    <maxVel>1.0</maxVel>
    <minDepth>0.002</minDepth>
    <material>Gazebo/DarkGrey</material>
  </gazebo>
  <gazebo reference="H1_F2_tip">
    <kp>1000000.0</kp>
    <kd>100.0</kd>
    <mu1>1.5</mu1>
    <mu2>1.5</mu2>
    <fdir1>1 0 0</fdir1>
    <maxVel>1.0</maxVel>
    <minDepth>0.002</minDepth>
    <material>Gazebo/DarkGrey</material>
  </gazebo>
  <gazebo reference="H1_F3_link_1">
    <kp>1000000.0</kp>
    <kd>100.0</kd>
    <mu1>1.5</mu1>
    <mu2>1.5</mu2>
    <fdir1>1 0 0</fdir1>
    <maxVel>1.0</maxVel>
    <minDepth>0.002</minDepth>
    <material>Gazebo/DarkGrey</material>
  </gazebo>
  <gazebo reference="H1_F3_link_2">
    <kp>1000000.0</kp>
    <kd>100.0</kd>
    <mu1>1.5</mu1>
    <mu2>1.5</mu2>
    <fdir1>1 0 0</fdir1>
    <maxVel>1.0</maxVel>
    <minDepth>0.002</minDepth>
    <material>Gazebo/DarkGrey</material>
  </gazebo>
  <gazebo reference="H1_F3_tip">
    <kp>1000000.0</kp>
    <kd>100.0</kd>
    <mu1>1.5</mu1>
    <mu2>1.5</mu2>
    <fdir1>1 0 0</fdir1>
    <maxVel>1.0</maxVel>
    <minDepth>0.002</minDepth>
    <material>Gazebo/DarkGrey</material>
  </gazebo>
  <gazebo reference="H1_F1_base_link">
    <kp>1000000.0</kp>
    <kd>100.0</kd>
    <mu1>1.5</mu1>
    <mu2>1.5</mu2>
    <fdir1>1 0 0</fdir1>
    <maxVel>1.0</maxVel>
    <minDepth>0.002</minDepth>
    <material>Gazebo/DarkGrey</material>
  </gazebo>
  <gazebo reference="H1_F2_base_link">
    <kp>1000000.0</kp>
    <kd>100.0</kd>
    <mu1>1.5</mu1>
    <mu2>1.5</mu2>
    <fdir1>1 0 0</fdir1>
    <maxVel>1.0</maxVel>
    <minDepth>0.002</minDepth>
    <material>Gazebo/DarkGrey</material>
  </gazebo>
  <gazebo reference="H1_F3_base_link">
    <kp>1000000.0</kp>
    <kd>100.0</kd>
    <mu1>1.5</mu1>
    <mu2>1.5</mu2>
    <fdir1>1 0 0</fdir1>
    <maxVel>1.0</maxVel>
    <minDepth>0.002</minDepth>
    <material>Gazebo/DarkGrey</material>
  </gazebo>
  <gazebo reference="H1_F1_palm_link">
    <kp>1000000.0</kp>
    <kd>100.0</kd>
    <mu1>1.5</mu1>
    <mu2>1.5</mu2>
    <fdir1>1 0 0</fdir1>
    <maxVel>1.0</maxVel>
    <minDepth>0.002</minDepth>
    <material>Gazebo/DarkGrey</material>
  </gazebo>
  <gazebo reference="H1_F2_palm_link">
    <kp>1000000.0</kp>
    <kd>100.0</kd>
    <mu1>1.5</mu1>
    <mu2>1.5</mu2>
    <fdir1>1 0 0</fdir1>
    <maxVel>1.0</maxVel>
    <minDepth>0.002</minDepth>
    <material>Gazebo/DarkGrey</material>
  </gazebo>
  <gazebo reference="H1_F3_palm_link">
    <kp>1000000.0</kp>
    <kd>100.0</kd>
    <mu1>1.5</mu1>
    <mu2>1.5</mu2>
    <fdir1>1 0 0</fdir1>
    <maxVel>1.0</maxVel>
    <minDepth>0.002</minDepth>
    <material>Gazebo/DarkGrey</material>
  </gazebo>
  <gazebo reference="H1_base_link">
    <kp>1000000.0</kp>
    <kd>100.0</kd>
    <mu1>1.5</mu1>
    <mu2>1.5</mu2>
    <fdir1>1 0 0</fdir1>
    <maxVel>1.0</maxVel>
    <minDepth>0.002</minDepth>
    <material>Gazebo/DarkGrey</material>
  </gazebo>
  <link name="world"/>
  <material name="white">
    <color rgba="1 1 1 1"/>
  </material>
  <link name="right_front_leg">
    <visual>
      <geometry>
        <box size="0.05 0.05 0.74"/>
      </geometry>
      <origin rpy="0 0 0" xyz="0 0 -0.37"/>
      <material name="white"/>
    </visual>
    <collision>
      <geometry>
        <box size="0.05 0.05 0.73"/>
      </geometry>
      <origin rpy="0 0 0" xyz="0 0 -0.37"/>
    </collision>
    <inertial>
      <mass value="1"/>
      <inertia ixx="1.0" ixy="0.0" ixz="0.0" iyy="1.0" iyz="0.0" izz="1.0"/>
    </inertial>
  </link>
  <joint name="base_to_right_front_leg" type="fixed">
    <parent link="plate"/>
    <child link="right_front_leg"/>
    <origin xyz="0.475 -0.775 -0.06"/>
  </joint>
  <gazebo reference="right_front_leg">
    <mu1>1.0</mu1>
    <mu2>1.0</mu2>
    <material>Gazebo/Wood</material>
  </gazebo>
  <!-- A bunch of stuff cut -->
  <link name="left_front_leg">
    <visual>
      <geometry>
        <box size="0.05 0.05 0.74"/>
      </geometry>
      <origin rpy="0 0 0" xyz="0 0 -0.37"/>
      <material name="white"/>
    </visual>
    <collision>
      <geometry>
        <box size="0.05 0.05 0.73"/>
      </geometry>
      <origin rpy="0 0 0" xyz="0 0 -0.37"/>
    </collision>
    <inertial>
      <mass value="1"/>
      <inertia ixx="1.0" ixy="0.0" ixz="0.0" iyy="1.0" iyz="0.0" izz="1.0"/>
    </inertial>
  </link>
  <joint name="base_to_left_front_leg" type="fixed">
    <parent link="plate"/>
    <child link="left_front_leg"/>
    <origin xyz="0.475 0.775 -0.06"/>
  </joint>
  <gazebo reference="left_front_leg">
    <mu1>1.0</mu1>
    <mu2>1.0</mu2>
    <material>Gazebo/Wood</material>
  </gazebo>
  <!-- A bunch of stuff cut -->
  <link name="right_back_leg">
    <visual>
      <geometry>
        <box size="0.05 0.05 0.74"/>
      </geometry>
      <origin rpy="0 0 0" xyz="0 0 -0.37"/>
      <material name="white"/>
    </visual>
    <collision>
      <geometry>
        <box size="0.05 0.05 0.73"/>
      </geometry>
      <origin rpy="0 0 0" xyz="0 0 -0.37"/>
    </collision>
    <inertial>
      <mass value="1"/>
      <inertia ixx="1.0" ixy="0.0" ixz="0.0" iyy="1.0" iyz="0.0" izz="1.0"/>
    </inertial>
  </link>
  <joint name="base_to_right_back_leg" type="fixed">
    <parent link="plate"/>
    <child link="right_back_leg"/>
    <origin xyz="-0.475 -0.775 -0.06"/>
  </joint>
  <gazebo reference="right_back_leg">
    <mu1>1.0</mu1>
    <mu2>1.0</mu2>
    <material>Gazebo/Wood</material>
  </gazebo>
  <!-- A bunch of stuff cut -->
  <link name="left_back_leg">
    <visual>
      <geometry>
        <box size="0.05 0.05 0.74"/>
      </geometry>
      <origin rpy="0 0 0" xyz="0 0 -0.37"/>
      <material name="white"/>
    </visual>
    <collision>
      <geometry>
        <box size="0.05 0.05 0.73"/>
      </geometry>
      <origin rpy="0 0 0" xyz="0 0 -0.37"/>
    </collision>
    <inertial>
      <mass value="1"/>
      <inertia ixx="1.0" ixy="0.0" ixz="0.0" iyy="1.0" iyz="0.0" izz="1.0"/>
    </inertial>
  </link>
  <joint name="base_to_left_back_leg" type="fixed">
    <parent link="plate"/>
    <child link="left_back_leg"/>
    <origin xyz="-0.475 0.775 -0.06"/>
  </joint>
  <gazebo reference="left_back_leg">
    <mu1>1.0</mu1>
    <mu2>1.0</mu2>
    <material>Gazebo/Wood</material>
  </gazebo>
  <!-- A bunch of stuff cut -->
  <link name="plate">
    <visual>
      <origin rpy="0.0 0.0 0.0" xyz="0.0 0.0 -0.03"/>
      <geometry>
        <box size="1.0 1.6 0.06"/>
      </geometry>
      <material name="white"/>
    </visual>
    <collision>
      <origin rpy="0.0 0.0 0.0" xyz="0.0 0.0 -0.03"/>
      <geometry>
        <box size="1.0 1.6 0.06"/>
      </geometry>
    </collision>
    <inertial>
      <mass value="5"/>
      <inertia ixx="1.0" ixy="0.0" ixz="0.0" iyy="1.0" iyz="0.0" izz="1.0"/>
    </inertial>
  </link>
  <gazebo reference="plate">
    <mu1>0.2</mu1>
    <mu2>0.2</mu2>
    <material>Gazebo/Yellow</material>
  </gazebo>
  <joint name="world_joint" type="fixed">
    <parent link="world"/>
    <child link="plate"/>
    <origin rpy="0.0 0.0 0.0" xyz="0.0 0.0 0.8"/>
  </joint>
  <joint name="pedestal_joint" type="fixed">
    <parent link="plate"/>
    <child link="pedestal"/>
    <origin rpy="0.0 0.0 0.0" xyz="-0.4 0.0 0.0"/>
  </joint>
  <link name="pedestal">
    <inertial>
      <mass value="10"/>
      <inertia ixx="1.0" ixy="0.0" ixz="0.0" iyy="1.0" iyz="0.0" izz="1.0"/>
    </inertial>
    <visual>
      <origin rpy="0 0 0" xyz="0 0 0.1"/>
      <geometry>
        <cylinder length="0.2" radius="0.1"/>
      </geometry>
      <material name="Gray">
        <color rgba="0.5 0.5 0.5 1"/>
      </material>
    </visual>
    <collision>
      <origin rpy="0 0 0" xyz="0 0 0.1"/>
      <geometry>
        <cylinder length="0.19" radius="0.1"/>
      </geometry>
    </collision>
  </link>
  <gazebo reference="pedestal">
    <mu1>0.2</mu1>
    <mu2>0.2</mu2>
    <material>Gazebo/Orange</material>
  </gazebo>
  <joint name="base_joint" type="fixed">
    <parent link="pedestal"/>
    <child link="base_link"/>
    <origin rpy="0.0 0.0 0.0" xyz="0.0 0.0 0.2"/>
  </joint>
  <link name="bin">
    <inertial>
      <mass value="3"/>
      <inertia ixx="1.0" ixy="0.0" ixz="0.0" iyy="1.0" iyz="0.0" izz="1.0"/>
    </inertial>
    <visual>
      <geometry>
        <mesh filename="package://ur5_data_collect_fw/meshes/bin.stl" scale="0.001 0.001 0.001"/>
      </geometry>
      <material name="red">
        <color rgba="0 0.8 0 1.000"/>
      </material>
    </visual>
    <collision>
      <geometry>
        <mesh filename="package://ur5_data_collect_fw/meshes/bin.stl" scale="0.001 0.001 0.001"/>
      </geometry>
    </collision>
  </link>
  <gazebo reference="bin">
    <mu1>0.2</mu1>
    <mu2>0.2</mu2>
    <material>Gazebo/Red</material>
  </gazebo>
  <gazebo reference="base_link">
    <mu1>0.2</mu1>
    <mu2>0.2</mu2>
    <material>Gazebo/Turquoise</material>
  </gazebo>
  <gazebo reference="shoulder_link">
    <mu1>0.2</mu1>
    <mu2>0.2</mu2>
    <material>Gazebo/Turquoise</material>
  </gazebo>
  <gazebo reference="upper_arm_link">
    <mu1>0.2</mu1>
    <mu2>0.2</mu2>
    <material>Gazebo/Turquoise</material>
  </gazebo>
  <gazebo reference="forearm_link">
    <mu1>0.2</mu1>
    <mu2>0.2</mu2>
    <material>Gazebo/Turquoise</material>
  </gazebo>
  <gazebo reference="wrist_1_link">
    <mu1>0.2</mu1>
    <mu2>0.2</mu2>
    <material>Gazebo/Turquoise</material>
  </gazebo>
  <gazebo reference="wrist_2_link">
    <mu1>0.2</mu1>
    <mu2>0.2</mu2>
    <material>Gazebo/Turquoise</material>
  </gazebo>
  <gazebo reference="wrist_3_link">
    <mu1>0.2</mu1>
    <mu2>0.2</mu2>
    <material>Gazebo/Turquoise</material>
  </gazebo>
  <joint name="bin_joint" type="fixed">
    <parent link="world"/>
    <child link="bin"/>
    <origin rpy="1.5707963267948966 0.0 0.0" xyz="-1.0 0.0 0.0"/>
  </joint>
  <gazebo>
    <plugin filename="libgazebo_grasp_fix.so" name="gazebo_grasp_fix">
      <arm>
        <arm_name>manipulator</arm_name>
        <palm_link>wrist_3_link</palm_link>
        <gripper_link>H1_F1_base_link</gripper_link>
        <gripper_link>H1_F1_link_1</gripper_link>
        <gripper_link>H1_F1_link_2</gripper_link>
        <gripper_link>H1_F1_tip</gripper_link>
        <gripper_link>H1_F2_base_link</gripper_link>
        <gripper_link>H1_F2_link_1</gripper_link>
        <gripper_link>H1_F2_link_2</gripper_link>
        <gripper_link>H1_F2_tip</gripper_link>
        <gripper_link>H1_F3_base_link</gripper_link>
        <gripper_link>H1_F3_link_1</gripper_link>
        <gripper_link>H1_F3_link_2</gripper_link>
        <gripper_link>H1_F3_tip</gripper_link>
      </arm>
      <forces_angle_tolerance>100</forces_angle_tolerance>
      <update_rate>4</update_rate>
      <grip_count_threshold>4</grip_count_threshold>
      <max_grip_count>8</max_grip_count>
      <release_tolerance>0.005</release_tolerance>
      <disable_collisions_on_attach>false</disable_collisions_on_attach>
      <contact_topic>__default_topic__</contact_topic>
    </plugin>
  </gazebo>
</robot>

